<?xml version="1.0" ?>
<robot name="lakme_bot">

  <!-- Define links -->
  <link name="base_link">
    <visual>
      <geometry>
        <box size="0.1 0.1 0.1" />
      </geometry>
    </visual>
  </link>

  <link name="link1">
    <visual>
      <geometry>
        <box size="0.2 0.2 1.0" />
      </geometry>
    </visual>
  </link>

  <link name="link2">
    <visual>
      <geometry>
        <box size="0.2 0.2 1.0" />
      </geometry>
    </visual>
  </link>

  <link name="link3">
    <visual>
      <geometry>
        <box size="0.2 0.2 1.0" />
      </geometry>
    </visual>
  </link>

  <link name="end_effector">
    <visual>
      <geometry>
        <box size="0.2 0.2 0.2" />
      </geometry>
    </visual>
  </link>

  <!-- Define joints -->
  <joint name="joint1" type="revolute">
    <origin xyz="0 0 0" rpy="0 0 0" />
    <parent link="base_link" />
    <child link="link1" />
    <axis xyz="0 0 1" />
    <limit lower="-3.14" upper="3.14" />
  </joint>

  <joint name="joint2" type="revolute">
    <origin xyz="0 0 1.0" rpy="0 0 0" />
    <parent link="link1" />
    <child link="link2" />
    <axis xyz="0 0 1" />
    <limit lower="-3.14" upper="3.14" />
  </joint>

  <joint name="joint3" type="revolute">
    <origin xyz="0 0 1.0" rpy="0 0 0" />
    <parent link="link2" />
    <child link="link3" />
    <axis xyz="0 0 1" />
    <limit lower="-3.14" upper="3.14" />
  </joint>

  <joint name="joint4" type="revolute">
    <origin xyz="0 0 1.0" rpy="0 0 0" />
    <parent link="link3" />
    <child link="end_effector" />
    <axis xyz="0 0 1" />
    <limit lower="-3.14" upper="3.14" />
  </joint>

</robot>
