<?xml version="1.0" ?>
<!-- =================================================================================== -->
<!-- |    This document was autogenerated by xacro from /workspace/src/ros2_RobotSimulation/ABBRobots/IRB120/irb120_ros2_gazebo/urdf/irb120.urdf.xacro | -->
<!-- |    EDITING THIS FILE BY HAND IS NOT RECOMMENDED                                 | -->
<!-- =================================================================================== -->
<robot name="irb120">
  <joint name="laser_joint" type="fixed">
    <parent link="base_link"/>
    <child link="laser_frame"/>
    <origin rpy="0 0 0" xyz="0.1 0 0.2"/>
  </joint>
  <link name="laser_frame">
    <visual>
      <geometry>
        <box size="0.01 0.01 0.01"/>
      </geometry>
      <material name="bblack"/>
    </visual>
    <collision>
      <geometry>
        <box size="0.01 0.01 0.01"/>
      </geometry>
    </collision>
  </link>
  <gazebo reference="laser_frame">
    <material>Gazebo/Red</material>
    <sensor name="laser" type="ray">
      <pose> 0 0 0 0 0 0 </pose>
      <visualize>true</visualize>
      <update_rate>10</update_rate>
      <ray>
        <scan>
          <horizontal>
            <samples>360</samples>
            <min_angle>-3.14</min_angle>
            <max_angle>3.14</max_angle>
          </horizontal>
        </scan>
        <range>
          <min>0.3</min>
          <max>12</max>
        </range>
      </ray>
      <plugin filename="libgazebo_ros_ray_sensor.so" name="laser_controller">
        <ros>
          <argument>~/out:=scan</argument>
        </ros>
        <output_type>sensor_msgs/LaserScan</output_type>
        <frame_name>laser_frame</frame_name>
      </plugin>
    </sensor>
  </gazebo>
  <joint name="camera_joint" type="fixed">
    <parent link="base_link"/>
    <child link="camera_link"/>
    <origin rpy="0 1.57 0" xyz="0.7 0 1.5"/>
  </joint>
  <link name="camera_link">
    <visual>
      <geometry>
        <box size="0.010 0.03 0.03"/>
      </geometry>
      <material name="black"/>
    </visual>
    <visual>
      <origin xyz="0 0 -0.05"/>
      <geometry>
        <cylinder length="0.1" radius="0.002"/>
      </geometry>
      <material name="black"/>
    </visual>
  </link>
  <joint name="camera_optical_joint" type="fixed">
    <parent link="camera_link"/>
    <child link="camera_link_optical"/>
    <origin rpy="-1.5707963267948966 0 -1.5707963267948966" xyz="0 0 0"/>
  </joint>
  <link name="camera_link_optical"/>
  <gazebo reference="camera_link">
    <material>Gazebo/Black</material>
    <sensor name="camera" type="camera">
      <pose> 0 0 0 0 0 0 </pose>
      <visualize>true</visualize>
      <update_rate>10</update_rate>
      <camera>
        <horizontal_fov>0.75</horizontal_fov>
        <image>
          <format>R8G8B8</format>
          <width>1000</width>
          <height>500</height>
        </image>
        <clip>
          <near>0.05</near>
          <far>8.0</far>
        </clip>
      </camera>
      <plugin filename="libgazebo_ros_camera.so" name="camera_controller">
        <frame_name>camera_link_optical</frame_name>
      </plugin>
    </sensor>
  </gazebo>
  <!--Sonar-->
  <joint name="end_effector_joint" type="fixed">
    <parent link="base_link"/>
    <child link="end_effector_link"/>
    <origin rpy="0 0 0" xyz="0.0 0.0 0.05"/>
  </joint>
  <link name="end_effector_link">
    <visual>
      <origin rpy="0 0 0" xyz="0 0 0"/>
      <geometry>
        <box size="0.05 0.05 0.05"/>
      </geometry>
      <material name="green"/>
    </visual>
    <collision>
      <origin rpy="0 0 0" xyz="0 0 0"/>
      <geometry>
        <box size="0.05 0.05 0.05"/>
      </geometry>
    </collision>
  </link>
  <gazebo reference="end_effector_link">
    <material>Gazebo/Green</material>
    <sensor name="end_effector_sensor" type="camera">
      <pose>0 0 0 0 0 0</pose>
      <visualize>true</visualize>
      <update_rate>10</update_rate>
      <camera>
        <horizontal_fov>1.57</horizontal_fov>
        <image>
          <format>R8G8B8</format>
          <width>640</width>
          <height>480</height>
        </image>
        <clip>
          <near>0.01</near>
          <far>10.0</far>
        </clip>
      </camera>
      <plugin filename="libgazebo_ros_camera.so" name="end_effector_controller">
        <frame_name>end_effector_link</frame_name>
      </plugin>
    </sensor>
  </gazebo>
  <!-- ===== ARGUMENTS ===== -->
  <!-- Conversion were obtained from http://www.e-paint.co.uk/Lab_values.asp
       unless otherwise stated. -->
  <transmission name="irb120_joint1_trans">
    <type>transmission_interface/SimpleTransmission</type>
    <joint name="irb120_joint1">
      <hardwareInterface>hardware_interface/PositionJointInterface</hardwareInterface>
    </joint>
    <actuator name="irb120_joint1_motor">
      <mechanicalReduction>1</mechanicalReduction>
    </actuator>
  </transmission>
  <transmission name="irb120_joint2_trans">
    <type>transmission_interface/SimpleTransmission</type>
    <joint name="irb120_joint2">
      <hardwareInterface>hardware_interface/PositionJointInterface</hardwareInterface>
    </joint>
    <actuator name="irb120_joint2_motor">
      <mechanicalReduction>1</mechanicalReduction>
    </actuator>
  </transmission>
  <transmission name="irb120_joint3_trans">
    <type>transmission_interface/SimpleTransmission</type>
    <joint name="irb120_joint3">
      <hardwareInterface>hardware_interface/PositionJointInterface</hardwareInterface>
    </joint>
    <actuator name="irb120_joint3_motor">
      <mechanicalReduction>1</mechanicalReduction>
    </actuator>
  </transmission>
  <transmission name="irb120_joint4_trans">
    <type>transmission_interface/SimpleTransmission</type>
    <joint name="irb120_joint4">
      <hardwareInterface>hardware_interface/PositionJointInterface</hardwareInterface>
    </joint>
    <actuator name="irb120_joint4_motor">
      <mechanicalReduction>1</mechanicalReduction>
    </actuator>
  </transmission>
  <transmission name="irb120_joint5_trans">
    <type>transmission_interface/SimpleTransmission</type>
    <joint name="irb120_joint5">
      <hardwareInterface>hardware_interface/PositionJointInterface</hardwareInterface>
    </joint>
    <actuator name="irb120_joint5_motor">
      <mechanicalReduction>1</mechanicalReduction>
    </actuator>
  </transmission>
  <transmission name="irb120_joint6_trans">
    <type>transmission_interface/SimpleTransmission</type>
    <joint name="irb120_joint6">
      <hardwareInterface>hardware_interface/PositionJointInterface</hardwareInterface>
    </joint>
    <actuator name="irb120_joint6_motor">
      <mechanicalReduction>1</mechanicalReduction>
    </actuator>
  </transmission>
  <!-- =================================== -->
  <!-- ========== END-EFFECTORS ========== -->
  <!-- === SCHUNK EGP-64 GRIPPER === -->
  <!-- ========== ROS2 CONTROL ========== -->
  <ros2_control name="GazeboSystem" type="system">
    <hardware>
      <plugin>gazebo_ros2_control/GazeboSystem</plugin>
    </hardware>
    <!-- irb120_joint1 -->
    <joint name="joint_1">
      <command_interface name="position">
        <param name="min">-2.87979</param>
        <param name="max">2.87979</param>
      </command_interface>
      <command_interface name="velocity">
        <param name="min">-4.36332</param>
        <param name="max">4.36332</param>
      </command_interface>
      <state_interface name="position"/>
      <state_interface name="velocity"/>
      <state_interface name="effort"/>
    </joint>
    <!-- irb120_joint2 -->
    <joint name="joint_2">
      <command_interface name="position">
        <param name="min">-1.91986</param>
        <param name="max">1.91986</param>
      </command_interface>
      <command_interface name="velocity">
        <param name="min">-4.36332</param>
        <param name="max">4.36332</param>
      </command_interface>
      <state_interface name="position"/>
      <state_interface name="velocity"/>
      <state_interface name="effort"/>
    </joint>
    <!-- irb120_joint3 -->
    <joint name="joint_3">
      <command_interface name="position">
        <param name="min">-1.91986</param>
        <param name="max">1.22173</param>
      </command_interface>
      <command_interface name="velocity">
        <param name="min">-4.36332</param>
        <param name="max">4.36332</param>
      </command_interface>
      <state_interface name="position"/>
      <state_interface name="velocity"/>
      <state_interface name="effort"/>
    </joint>
    <!-- irb120_joint4 -->
    <joint name="joint_4">
      <command_interface name="position">
        <param name="min">-2.79253</param>
        <param name="max">2.79253</param>
      </command_interface>
      <command_interface name="velocity">
        <param name="min">-5.58505</param>
        <param name="max">5.58505</param>
      </command_interface>
      <state_interface name="position"/>
      <state_interface name="velocity"/>
      <state_interface name="effort"/>
    </joint>
    <!-- irb120_joint5 -->
    <joint name="joint_5">
      <command_interface name="position">
        <param name="min">-2.094395</param>
        <param name="max">2.094395</param>
      </command_interface>
      <command_interface name="velocity">
        <param name="min">-5.58505</param>
        <param name="max">5.58505</param>
      </command_interface>
      <state_interface name="position"/>
      <state_interface name="velocity"/>
      <state_interface name="effort"/>
    </joint>
    <!-- irb120_joint6 -->
    <joint name="joint_6">
      <command_interface name="position">
        <param name="min">-6.98132</param>
        <param name="max">6.98132</param>
      </command_interface>
      <command_interface name="velocity">
        <param name="min">-7.33038</param>
        <param name="max">7.33038</param>
      </command_interface>
      <state_interface name="position"/>
      <state_interface name="velocity"/>
      <state_interface name="effort"/>
    </joint>
    <!-- =================================== -->
    <!-- ========== END-EFFECTORS ========== -->
    <!-- === SCHUNK EGP-64 GRIPPER === -->
  </ros2_control>
  <gazebo reference="base_link">
    <selfCollide>false</selfCollide>
  </gazebo>
  <gazebo reference="link_1">
    <selfCollide>false</selfCollide>
  </gazebo>
  <gazebo reference="link_2">
    <selfCollide>false</selfCollide>
  </gazebo>
  <gazebo reference="link_3">
    <selfCollide>false</selfCollide>
  </gazebo>
  <gazebo reference="link_4">
    <selfCollide>false</selfCollide>
  </gazebo>
  <gazebo reference="link_5">
    <selfCollide>false</selfCollide>
  </gazebo>
  <gazebo reference="link_6">
    <selfCollide>false</selfCollide>
  </gazebo>
  <!-- =================================== -->
  <!-- ========== END-EFFECTORS ========== -->
  <!-- === SCHUNK EGP-64 GRIPPER === -->
  <gazebo reference="end_effector_frame_fixed_joint">
    <preserveFixedJoint>true</preserveFixedJoint>
    <!-- For compatibility with SDFormat < 4.4 -->
    <disableFixedJointLumping>true</disableFixedJointLumping>
  </gazebo>
  <!-- ***** ABB-IRB120 ROBOT .urdf SERIAL CHAIN ***** -->
  <!-- Link list: -->
  <!-- base_link -->
  <link name="base_link">
    <inertial>
      <mass value="6.215"/>
      <origin rpy="0 0 0" xyz="-0.04204 8.01E-05 0.07964"/>
      <inertia ixx="0.0247272" ixy="-8.0784E-05" ixz="0.00130902" iyy="0.0491285" iyz="-8.0419E-06" izz="0.0472376"/>
    </inertial>
    <visual>
      <origin rpy="0 0 0" xyz="0 0 0"/>
      <geometry>
        <mesh filename="file:///workspace/install/irb120_ros2_gazebo/share/irb120_ros2_gazebo/meshes/visual/base_link.dae"/>
      </geometry>
      <material name="">
        <color rgba="0.7372549 0.3490196 0.1607843 1"/>
      </material>
    </visual>
    <collision>
      <origin rpy="0 0 0" xyz="0 0 0"/>
      <geometry>
        <mesh filename="file:///workspace/install/irb120_ros2_gazebo/share/irb120_ros2_gazebo/meshes/collision/base_link.stl"/>
      </geometry>
      <material name="">
        <color rgba="1 1 0 1"/>
      </material>
    </collision>
  </link>
  <!-- link_1 -->
  <link name="link_1">
    <inertial>
      <mass value="3.067"/>
      <origin rpy="0 0 0" xyz="9.77E-05 -0.00012 0.23841"/>
      <inertia ixx="0.0142175" ixy="-1.28579E-05" ixz="-2.31364E-05" iyy="0.0144041" iyz="1.93404E-05" izz="0.0104533"/>
    </inertial>
    <visual>
      <origin rpy="0 0 0" xyz="0 0 0"/>
      <geometry>
        <mesh filename="file:///workspace/install/irb120_ros2_gazebo/share/irb120_ros2_gazebo/meshes/visual/link_1.dae"/>
      </geometry>
      <material name="">
        <color rgba="0.7372549 0.3490196 0.1607843 1"/>
      </material>
    </visual>
    <collision>
      <origin rpy="0 0 0" xyz="0 0 0"/>
      <geometry>
        <mesh filename="file:///workspace/install/irb120_ros2_gazebo/share/irb120_ros2_gazebo/meshes/collision/link_1.stl"/>
      </geometry>
      <material name="">
        <color rgba="1 1 0 1"/>
      </material>
    </collision>
  </link>
  <!-- link_2 -->
  <link name="link_2">
    <inertial>
      <mass value="3.909"/>
      <origin rpy="0 0 0" xyz="0.00078 -0.00212 0.10124"/>
      <inertia ixx="0.0603111" ixy="9.83431E-06" ixz="5.72407E-05" iyy="0.041569" iyz="-0.00050497" izz="0.0259548"/>
    </inertial>
    <visual>
      <origin rpy="0 0 0" xyz="0 0 0"/>
      <geometry>
        <mesh filename="file:///workspace/install/irb120_ros2_gazebo/share/irb120_ros2_gazebo/meshes/visual/link_2.dae"/>
      </geometry>
      <material name="">
        <color rgba="0.7372549 0.3490196 0.1607843 1"/>
      </material>
    </visual>
    <collision>
      <origin rpy="0 0 0" xyz="0 0 0"/>
      <geometry>
        <mesh filename="file:///workspace/install/irb120_ros2_gazebo/share/irb120_ros2_gazebo/meshes/collision/link_2.stl"/>
      </geometry>
      <material name="">
        <color rgba="1 1 0 1"/>
      </material>
    </collision>
  </link>
  <!-- link_3 -->
  <link name="link_3">
    <inertial>
      <mass value="2.944"/>
      <origin rpy="0 0 0" xyz="0.02281 0.00106 0.05791"/>
      <inertia ixx="0.00835606" ixy="-8.01545E-05" ixz="0.00142884" iyy="0.016713" iyz="-0.000182227" izz="0.0126984"/>
    </inertial>
    <visual>
      <origin rpy="0 0 0" xyz="0 0 0"/>
      <geometry>
        <mesh filename="file:///workspace/install/irb120_ros2_gazebo/share/irb120_ros2_gazebo/meshes/visual/link_3.dae"/>
      </geometry>
      <material name="">
        <color rgba="0.7372549 0.3490196 0.1607843 1"/>
      </material>
    </visual>
    <collision>
      <origin rpy="0 0 0" xyz="0 0 0"/>
      <geometry>
        <mesh filename="file:///workspace/install/irb120_ros2_gazebo/share/irb120_ros2_gazebo/meshes/collision/link_3.stl"/>
      </geometry>
      <material name="">
        <color rgba="1 1 0 1"/>
      </material>
    </collision>
  </link>
  <!-- link_4 -->
  <link name="link_4">
    <inertial>
      <mass value="1.328"/>
      <origin rpy="0 0 0" xyz="0.2247 0.00015 0.00041"/>
      <inertia ixx="0.00284661" ixy="-2.12765E-05" ixz="-1.6435E-05" iyy="0.00401346" iyz="1.31336E-05" izz="0.0052535"/>
    </inertial>
    <visual>
      <origin rpy="0 0 0" xyz="0 0 0"/>
      <geometry>
        <mesh filename="file:///workspace/install/irb120_ros2_gazebo/share/irb120_ros2_gazebo/meshes/visual/link_4.dae"/>
      </geometry>
      <material name="">
        <color rgba="0.7372549 0.3490196 0.1607843 1"/>
      </material>
    </visual>
    <collision>
      <origin rpy="0 0 0" xyz="0 0 0"/>
      <geometry>
        <mesh filename="file:///workspace/install/irb120_ros2_gazebo/share/irb120_ros2_gazebo/meshes/collision/link_4.stl"/>
      </geometry>
      <material name="">
        <color rgba="1 1 0 1"/>
      </material>
    </collision>
  </link>
  <!-- link_5 -->
  <link name="link_5">
    <inertial>
      <mass value="0.546"/>
      <origin rpy="0 0 0" xyz="-0.00109 3.68E-05 6.22E-05"/>
      <inertia ixx="0.000404891" ixy="1.61943E-06" ixz="8.46805E-07" iyy="0.000892825" iyz="-1.51792E-08" izz="0.000815468"/>
    </inertial>
    <visual>
      <origin rpy="0 0 0" xyz="0 0 0"/>
      <geometry>
        <mesh filename="file:///workspace/install/irb120_ros2_gazebo/share/irb120_ros2_gazebo/meshes/visual/link_5.dae"/>
      </geometry>
      <material name="">
        <color rgba="0.7372549 0.3490196 0.1607843 1"/>
      </material>
    </visual>
    <collision>
      <origin rpy="0 0 0" xyz="0 0 0"/>
      <geometry>
        <mesh filename="file:///workspace/install/irb120_ros2_gazebo/share/irb120_ros2_gazebo/meshes/collision/link_5.stl"/>
      </geometry>
      <material name="">
        <color rgba="1 1 0 1"/>
      </material>
    </collision>
  </link>
  <!-- link_6 -->
  <link name="link_6">
    <inertial>
      <mass value="0.137"/>
      <origin rpy="0 0 0" xyz="-0.00706 -0.00017 -1.32E-06"/>
      <inertia ixx="0.001" ixy="0" ixz="0" iyy="0.001" iyz="0" izz="0.001"/>
    </inertial>
    <visual>
      <origin rpy="0 0 0" xyz="0 0 0"/>
      <geometry>
        <mesh filename="file:///workspace/install/irb120_ros2_gazebo/share/irb120_ros2_gazebo/meshes/visual/link_6.dae"/>
      </geometry>
      <material name="">
        <color rgba="0.1882353 0.1960784 0.2039216 1"/>
      </material>
    </visual>
    <collision>
      <origin rpy="0 0 0" xyz="0 0 0"/>
      <geometry>
        <mesh filename="file:///workspace/install/irb120_ros2_gazebo/share/irb120_ros2_gazebo/meshes/collision/link_6.stl"/>
      </geometry>
      <material name="">
        <color rgba="1 1 0 1"/>
      </material>
    </collision>
  </link>
  <!-- end of link list -->
  <!-- Joint list: -->
  <!-- joint_1 -->
  <joint name="joint_1" type="revolute">
    <origin rpy="0 0 0" xyz="0 0 0"/>
    <parent link="base_link"/>
    <child link="link_1"/>
    <limit effort="0" lower="-2.87979" upper="2.87979" velocity="4.36332"/>
    <axis xyz="0 0 1"/>
    <dynamics damping="50.0" friction="1.0"/>
  </joint>
  <!-- joint_2 -->
  <joint name="joint_2" type="revolute">
    <origin rpy="0 0 0" xyz="0 0 0.29"/>
    <parent link="link_1"/>
    <child link="link_2"/>
    <limit effort="0" lower="-1.91986" upper="1.91986" velocity="4.36332"/>
    <axis xyz="0 1 0"/>
    <dynamics damping="50.0" friction="1.0"/>
  </joint>
  <!-- joint_3 -->
  <joint name="joint_3" type="revolute">
    <origin rpy="0 0 0" xyz="0 0 0.27"/>
    <parent link="link_2"/>
    <child link="link_3"/>
    <limit effort="0" lower="-1.91986" upper="1.22173" velocity="4.36332"/>
    <axis xyz="0 1 0"/>
    <dynamics damping="10.0" friction="1.0"/>
  </joint>
  <!-- joint_4 -->
  <joint name="joint_4" type="revolute">
    <origin rpy="0 0 0" xyz="0 0 0.07"/>
    <parent link="link_3"/>
    <child link="link_4"/>
    <limit effort="0" lower="-2.79253" upper="2.79253" velocity="5.58505"/>
    <axis xyz="1 0 0"/>
    <dynamics damping="5.0" friction="1.0"/>
  </joint>
  <!-- joint_5 -->
  <joint name="joint_5" type="revolute">
    <origin rpy="0 0 0" xyz="0.302 0 0"/>
    <parent link="link_4"/>
    <child link="link_5"/>
    <limit effort="0" lower="-2.094395" upper="2.094395" velocity="5.58505"/>
    <axis xyz="0 1 0"/>
    <dynamics damping="2.0" friction="1.0"/>
  </joint>
  <!-- joint_6 -->
  <joint name="joint_6" type="revolute">
    <origin rpy="0 0 0" xyz="0.072 0 0"/>
    <parent link="link_5"/>
    <child link="link_6"/>
    <limit effort="0" lower="-6.98132" upper="6.98132" velocity="7.33038"/>
    <axis xyz="1 0 0"/>
    <dynamics damping="1.0" friction="1.0"/>
  </joint>
  <!-- end of joint list -->
  <!-- ROS-Industrial 'base' frame: base_link to ABB World Coordinates transform -->
  <link name="base"/>
  <joint name="base_link-base" type="fixed">
    <origin rpy="0 0 0" xyz="0 0 0"/>
    <parent link="base_link"/>
    <child link="base"/>
  </joint>
  <!-- ROS-Industrial 'flange' frame: attachment point for EEF models -->
  <link name="flange"/>
  <joint name="joint_6-flange" type="fixed">
    <origin rpy="0 0 0" xyz="0 0 0"/>
    <parent link="link_6"/>
    <child link="flange"/>
  </joint>
  <!-- ROS-Industrial 'tool0' frame: all-zeros tool frame -->
  <link name="tool0"/>
  <joint name="link_6-tool0" type="fixed">
    <origin rpy="0 1.5707963267948966 0" xyz="0 0 0"/>
    <parent link="flange"/>
    <child link="tool0"/>
  </joint>
  <!-- =================================== -->
  <!-- ========== END-EFFECTORS ========== -->
  <!-- === SCHUNK EGP-64 GRIPPER === -->
  <!-- Gazebo WORLD link: -->
  <link name="world"/>
  <!-- ========== ========== ========== ========== ========== ========== -->
  <!-- CELL LAYOUT SELECTION: -->
</robot>
