<?xml version="1.0" ?>
<robot name="team11_bot">
    <link name="world" />
    <link name="base_link">
        <visual>
            <geometry>
                <cylinder length="0.05" radius="0.1" />
            </geometry>
            <material name="silver">
                <color rgba="0.75 0.75 0.75 1" />
            </material>
            <origin rpy="0 0 0" xyz="0 0 0.025" />
        </visual>
        <collision>
            <geometry>
                <cylinder length="0.05" radius="0.1" />
            </geometry>
            <origin rpy="0 0 0" xyz="0 0 0.025" />
        </collision>
        
<inertial>
            <mass value="0.1" />
            <inertia ixx="0.03" iyy="0.03" izz="0.03" ixy="0.0" ixz="0.0" iyz="0.0" />
        </inertial>

    </link>
    <joint name="fixed" type="fixed">
        <parent link="world" />
        <child link="base_link" />
    </joint>
    <link name="torso">
        <visual>
            <geometry>
                <cylinder length="0.5" radius="0.05" />
            </geometry>
            <material name="silver">
                <color rgba="0.75 0.75 0.75 1" />
            </material>
            <origin rpy="0 0 0" xyz="0 0 0.25" />
        </visual>
        <collision>
            <geometry>
                <cylinder length="0.5" radius="0.05" />
            </geometry>
            <origin rpy="0 0 0" xyz="0 0 0.25" />
        </collision>
        
<inertial>
            <mass value="0.1" />
            <inertia ixx="0.03" iyy="0.03" izz="0.03" ixy="0.0" ixz="0.0" iyz="0.0" />
        </inertial>

    </link>
    <joint name="hip" type="continuous">
        <axis xyz="0 0 1" />
        <parent link="base_link" />
        <child link="torso" />
        <origin rpy="0 0 0" xyz="0.0 0.0 0.05" />
    </joint>
    <link name="upper_arm">
        <visual>
            <geometry>
                <cylinder length="0.4" radius="0.05" />
            </geometry>
            <material name="red" />
            <origin rpy="0 0 0" xyz="0 0 0.2" />
        </visual>
        <collision>
            <geometry>
                <cylinder length="0.4" radius="0.05" />
            </geometry>
            <origin rpy="0 0 0" xyz="0 0 0.2" />
        </collision>
        
<inertial>
            <mass value="0.1" />
            <inertia ixx="0.03" iyy="0.03" izz="0.03" ixy="0.0" ixz="0.0" iyz="0.0" />
        </inertial>

    </link>
    <joint name="shoulder" type="continuous">
        <axis xyz="0 1 0" />
        <parent link="torso" />
        <child link="upper_arm" />
        <origin rpy="0 1.5708 0" xyz="0.0 0.0 0.45" />
    </joint>
    <link name="lower_arm">
        <visual>
            <geometry>
                <cylinder length="0.4" radius="0.05" />
            </geometry>
            <material name="silver" />
            <origin rpy="0 0 0" xyz="0 0 0.2" />
        </visual>
        <collision>
            <geometry>
                <cylinder length="0.4" radius="0.05" />
            </geometry>
            <origin rpy="0 0 0" xyz="0 0 0.2" />
        </collision>
        
<inertial>
            <mass value="0.1" />
            <inertia ixx="0.03" iyy="0.03" izz="0.03" ixy="0.0" ixz="0.0" iyz="0.0" />
        </inertial>

    </link>
    <joint name="elbow" type="continuous">
        <axis xyz="0 1 0" />
        <parent link="upper_arm" />
        <child link="lower_arm" />
        <origin rpy="0 0 0" xyz="0.0 0.0 0.35" />
    </joint>
    <link name="hand">
        <visual>
            <geometry>
                <box size="0.05 0.05 0.05" />
            </geometry>
            <material name="blue" />
        </visual>
        <collision>
            <geometry>
                <box size="0.05 0.05 0.05" />
            </geometry>
        </collision>
        
<inertial>
            <mass value="0.1" />
            <inertia ixx="0.03" iyy="0.03" izz="0.03" ixy="0.0" ixz="0.0" iyz="0.0" />
        </inertial>

    </link>
    <joint name="wrist" type="continuous">
        <axis xyz="0 1 0" />
        <parent link="lower_arm" />
        <child link="hand" />
        <origin rpy="0 0 0" xyz="0.0 0.0 0.425" />
    </joint>
    
    
    
    
    <!--
    <gazebo reference="base_link">
        <sensor type="ray" name="hokuyo">
            <pose>0 0 0 0 0 0</pose>
            <visualize>true</visualize>
            <update_rate>40</update_rate>
            <ray>
                <scan>
                    <horizontal>
                        <samples>720</samples>
                        <resolution>1</resolution>
                        <min_angle>-1.570796</min_angle>
                        <max_angle>1.570796</max_angle>
                    </horizontal>
                </scan>
                <range>
                    <min>0.10</min>
                    <max>30.0</max>
                    <resolution>0.01</resolution>
                </range>
            </ray>
            <plugin name="gpu_laser" filename="libgazebo_ros_laser.so">
                <topicName>/scan</topicName>
                <frameName>base_hokuyo_link</frameName>
            </plugin>
        </sensor>
    </gazebo>
-->
    
    
    <transmission name="trans_hip">
        <type>transmission_interface/SimpleTransmission</type>
        <joint name="hip">
            <hardwareInterface>hardware_interface/PositionJointInterface</hardwareInterface>
        </joint>
        <actuator name="hip_motor">
            <hardwareInterface>hardware_interface/PositionJointInterface</hardwareInterface>
            <mechanicalReduction>1</mechanicalReduction>
        </actuator>
    </transmission>
    <transmission name="trans_shoulder">
        <type>transmission_interface/SimpleTransmission</type>
        <joint name="shoulder">
            <hardwareInterface>hardware_interface/PositionJointInterface</hardwareInterface>
        </joint>
        <actuator name="shoulder_motor">
            <hardwareInterface>hardware_interface/PositionJointInterface</hardwareInterface>
            <mechanicalReduction>1</mechanicalReduction>
        </actuator>
    </transmission>
    <transmission name="trans_elbow">
        <type>transmission_interface/SimpleTransmission</type>
        <joint name="elbow">
            <hardwareInterface>hardware_interface/PositionJointInterface</hardwareInterface>
        </joint>
        <actuator name="elbow_motor">
            <hardwareInterface>hardware_interface/PositionJointInterface</hardwareInterface>
            <mechanicalReduction>1</mechanicalReduction>
        </actuator>
    </transmission>
    <transmission name="trans_wrist">
        <type>transmission_interface/SimpleTransmission</type>
        <joint name="wrist">
            <hardwareInterface>hardware_interface/PositionJointInterface</hardwareInterface>
        </joint>
        <actuator name="wrist_motor">
            <hardwareInterface>hardware_interface/PositionJointInterface</hardwareInterface>
            <mechanicalReduction>1</mechanicalReduction>
        </actuator>
    </transmission>
    
    



    <gazebo>
        <plugin name="gazebo_grasp_fix" filename="libgazebo_grasp_fix.so">
            <arm>
                <arm_name>arm</arm_name>
                <palm_link>hand</palm_link>
                
                
            </arm>
            <forces_angle_tolerance>100</forces_angle_tolerance>
            <update_rate>4</update_rate>
            <grip_count_threshold>4</grip_count_threshold>
            <max_grip_count>8</max_grip_count>
            <release_tolerance>0.005</release_tolerance>
            <disable_collisions_on_attatch>false</disable_collisions_on_attatch>
            <contact_topic>_default_topic_</contact_topic>
        </plugin>
    </gazebo>

    

    <gazebo>
        <plugin name="gazebo_ros_control" filename="libgazebo_ros_control.so">
            <robotNamespace>/</robotNamespace>
        </plugin>
    </gazebo>
    <gazebo>
        <plugin name="joint_state_publisher" filename="libgazebo_ros_joint_state_publisher.so">
            <jointName>hip, shoulder, elbow, wrist</jointName>
        </plugin>
    </gazebo>
</robot>