<?xml version="1.0"?>
<robot xmlns:xacro="http://www.ros.org/wiki/xacro">

  <xacro:include filename="inertial_macros.xacro" />

  <material name="white">
    <color rgba="1 1 1 1" />
  </material>

  <material name="orange">
    <color rgba="1 0.3 0.1 1" />
  </material>

  <material name="blue">
    <color rgba="0.2 0.2 1 1" />
  </material>

  <material name="black">
    <color rgba="0 0 0 1" />
  </material>

  <!-- BASE LINK -->
  <!-- Update Base Link -->

  <link name="base_link">
    <child link="chassis" />
    <child link="left_wheel" />
    <child link="right_wheel" />
    <child link="caster_wheel" />
    <child link="cylinder_link" />
  </link>



  <!-- CHASSIS LINK -->

  <joint name="chassis_joint" type="fixed">
    <parent link="base_link" />
    <child link="chassis" />
    <origin xyz="-0.1 0 0" />
  </joint>

  <link name="chassis">
    <visual>
      <origin xyz="0.15 0 0.075" />
      <geometry>
        <box size="0.3 0.3 0.15" />
      </geometry>
      <material name="white" />
    </visual>
    <collision>
      <origin xyz="0.15 0 0.075" />
      <geometry>
        <box size="0.3 0.3 0.15" />
      </geometry>
    </collision>
    <xacro:inertial_box mass="0.5" x="0.3" y="0.3" z="0.15">
      <origin xyz="0.15 0 0.075" rpy="0 0 0" />
    </xacro:inertial_box>
  </link>

  <!-- LEFT WHEEL LINK -->

  <joint name="left_wheel_joint" type="continuous">
    <parent link="base_link" />
    <child link="left_wheel" />
    <origin xyz="0 0.175 0" rpy="-${pi/2} 0 0" />
    <axis xyz="0 0 1" />
  </joint>

  <link name="left_wheel">
    <visual>
      <geometry>
        <cylinder radius="0.05" length="0.04" />
      </geometry>
      <material name="blue" />
    </visual>
    <collision>
      <geometry>
        <cylinder radius="0.05" length="0.04" />
      </geometry>
    </collision>
    <xacro:inertial_cylinder mass="0.1" length="0.04" radius="0.05">
      <origin xyz="0 0 0" rpy="0 0 0" />
    </xacro:inertial_cylinder>
  </link>

  <!-- RIGHT WHEEL LINK -->

  <joint name="right_wheel_joint" type="continuous">
    <parent link="base_link" />
    <child link="right_wheel" />
    <origin xyz="0 -0.175 0" rpy="${pi/2} 0 0" />
    <axis xyz="0 0 -1" />
  </joint>

  <link name="right_wheel">
    <visual>
      <geometry>
        <cylinder radius="0.05" length="0.04" />
      </geometry>
      <material name="blue" />
    </visual>
    <collision>
      <geometry>
        <cylinder radius="0.05" length="0.04" />
      </geometry>
    </collision>
    <xacro:inertial_cylinder mass="0.1" length="0.04" radius="0.05">
      <origin xyz="0 0 0" rpy="0 0 0" />
    </xacro:inertial_cylinder>
  </link>

  <!-- CASTER WHEEL LINK -->

  <joint name="caster_wheel_joint" type="fixed">
    <parent link="chassis" />
    <child link="caster_wheel" />
    <origin xyz="0.24 0 0" />
  </joint>

  <link name="caster_wheel">
    <visual>
      <geometry>
        <sphere radius="0.05" />
      </geometry>
      <material name="black" />
    </visual>
    <collision>
      <geometry>
        <sphere radius="0.05" />
      </geometry>
    </collision>
    <xacro:inertial_sphere mass="0.1" radius="0.05">
      <origin xyz="0 0 0" rpy="0 0 0" />
    </xacro:inertial_sphere>
  </link>

  <!-- CYLINDER JOINT -->

  <joint name="cylinder_joint" type="continuous">
    <parent link="chassis" />
    <child link="cylinder_link" />
    <origin xyz="0.15 0 0.15" rpy="0 0 0" />
    <axis xyz="0 0 1" />
  </joint>

  <!-- CYLINDER LINK -->

  <link name="cylinder_link">
    <visual>
      <geometry>
        <cylinder radius="0.03" length="0.4" />
      </geometry>
      <material name="blue" />
    </visual>
    <collision>
      <geometry>
        <cylinder radius="0.03" length="0.4" />
      </geometry>
    </collision>
    <xacro:inertial_cylinder mass="0.05" length="0.4" radius="0.03">
      <origin xyz="0 0 0" rpy="0 0 0" />
    </xacro:inertial_cylinder>
  </link>


    <!-- NEW JOINT -->
    <joint name="new_joint" type="revolute">
      <parent link="cylinder_link" />
      <child link="new_link" />
  <origin xyz="0 0 0.2" rpy="0 1.5708 0" />
  <axis xyz="0 1 0" />
  <limit lower="${-pi}" upper="${pi/4}" velocity="100" effort="100"/> 
    </joint>

    <!-- NEW LINK -->
<link name="new_link">
  <visual>
  <origin xyz="0 0 0.15" rpy="0 0 0" />
    <geometry>
      <cylinder radius="0.03" length="0.3" />
    </geometry>
    <material name="yellow" />
  </visual>
  <collision>
    <geometry>
      <cylinder radius="0.03" length="0.3" />
    </geometry>
  </collision>
  <inertial>
    <mass value="0.01" />
    <origin xyz="0 0 0" rpy="0 0 0" />
    <inertia ixx="0.0001" ixy="0" ixz="0" iyy="0.0001" iyz="0" izz="0.0001" />
  </inertial>
</link>


     <joint name="camera_joint" type="fixed">
        <origin xyz="-0.1 0 0.3" rpy="0 -1.5708 0" />
        <parent link="new_link"/>
        <child link="camera_link"/>        
    </joint>


    <!-- camera_link describes the camera at the end of the arm -->
    <!-- - It has multiple visual elements, which ultimately get combined together -->
    <!-- - Even if we specify different materials, RViz will just colour them all the same as the first -->
    <!-- - Although we could also specify multiple collision geometries, instead we just use a single box that encompasses the whole camera -->
    <link name="camera_link">
        <visual>
            <origin xyz="-0.03 0 0" rpy="0 0 0"/>
            <geometry>
                <box size="0.06 0.15 0.15" />
            </geometry>
            <material name="red" />
        </visual>
        <visual>
            <origin xyz="0.03 0 0" rpy="0 ${pi/2} 0"/>
            <geometry>
                <cylinder length="0.06" radius="0.04" />
            </geometry>
            <material name="red" />
        </visual>
        <collision>
            <origin xyz="0.0 0 0" rpy="0 0 0"/>
            <geometry>
                <box size="0.12 0.15 0.15" />
            </geometry>
        </collision>
        <xacro:inertial_box mass="0.1" x="0.12" y="0.15" z="0.15">
            <origin xyz="0.0 0 0" rpy="0 0 0"/>
        </xacro:inertial_box>
    </link>


</robot>

